[2025-07-20T12:57:17.833+0000] {taskinstance.py:1956} INFO - Dependencies all met for dep_context=non-requeueable deps ti=<TaskInstance: ETL_Pipeline.ingest_raw_data manual__2025-07-20T12:57:12.584468+00:00 [queued]>
[2025-07-20T12:57:17.840+0000] {taskinstance.py:1956} INFO - Dependencies all met for dep_context=requeueable deps ti=<TaskInstance: ETL_Pipeline.ingest_raw_data manual__2025-07-20T12:57:12.584468+00:00 [queued]>
[2025-07-20T12:57:17.841+0000] {taskinstance.py:2170} INFO - Starting attempt 1 of 2
[2025-07-20T12:57:17.852+0000] {taskinstance.py:2191} INFO - Executing <Task(PythonOperator): ingest_raw_data> on 2025-07-20 12:57:12.584468+00:00
[2025-07-20T12:57:17.865+0000] {standard_task_runner.py:60} INFO - Started process 295 to run task
[2025-07-20T12:57:17.871+0000] {standard_task_runner.py:87} INFO - Running: ['***', 'tasks', 'run', 'ETL_Pipeline', 'ingest_raw_data', 'manual__2025-07-20T12:57:12.584468+00:00', '--job-id', '41', '--raw', '--subdir', 'DAGS_FOLDER/etl_dag.py', '--cfg-path', '/tmp/tmpzn4p1yg8']
[2025-07-20T12:57:17.875+0000] {standard_task_runner.py:88} INFO - Job 41: Subtask ingest_raw_data
[2025-07-20T12:57:17.929+0000] {task_command.py:423} INFO - Running <TaskInstance: ETL_Pipeline.ingest_raw_data manual__2025-07-20T12:57:12.584468+00:00 [running]> on host bd03fb9553b0
[2025-07-20T12:57:17.993+0000] {taskinstance.py:2480} INFO - Exporting env vars: AIRFLOW_CTX_DAG_OWNER='Jhabindra Aryal' AIRFLOW_CTX_DAG_ID='ETL_Pipeline' AIRFLOW_CTX_TASK_ID='ingest_raw_data' AIRFLOW_CTX_EXECUTION_DATE='2025-07-20T12:57:12.584468+00:00' AIRFLOW_CTX_TRY_NUMBER='1' AIRFLOW_CTX_DAG_RUN_ID='manual__2025-07-20T12:57:12.584468+00:00'
[2025-07-20T12:57:19.175+0000] {logging_mixin.py:188} INFO - Saved raw text to data/raw/data
[2025-07-20T12:57:19.190+0000] {logging_mixin.py:188} INFO - Created DataFrame with 574 lines of text
[2025-07-20T12:57:19.192+0000] {connectionpool.py:824} WARNING - Retrying (Retry(total=4, connect=None, read=None, redirect=None, status=None)) after connection broken by 'NewConnectionError('<urllib3.connection.HTTPConnection object at 0x785777164670>: Failed to establish a new connection: [Errno 111] Connection refused')': /raw?location=
[2025-07-20T12:57:19.594+0000] {connectionpool.py:824} WARNING - Retrying (Retry(total=3, connect=None, read=None, redirect=None, status=None)) after connection broken by 'NewConnectionError('<urllib3.connection.HTTPConnection object at 0x7857771648e0>: Failed to establish a new connection: [Errno 111] Connection refused')': /raw?location=
[2025-07-20T12:57:20.397+0000] {connectionpool.py:824} WARNING - Retrying (Retry(total=2, connect=None, read=None, redirect=None, status=None)) after connection broken by 'NewConnectionError('<urllib3.connection.HTTPConnection object at 0x785777164af0>: Failed to establish a new connection: [Errno 111] Connection refused')': /raw?location=
[2025-07-20T12:57:22.001+0000] {connectionpool.py:824} WARNING - Retrying (Retry(total=1, connect=None, read=None, redirect=None, status=None)) after connection broken by 'NewConnectionError('<urllib3.connection.HTTPConnection object at 0x785777152d00>: Failed to establish a new connection: [Errno 111] Connection refused')': /raw?location=
[2025-07-20T12:57:25.205+0000] {connectionpool.py:824} WARNING - Retrying (Retry(total=0, connect=None, read=None, redirect=None, status=None)) after connection broken by 'NewConnectionError('<urllib3.connection.HTTPConnection object at 0x785777164d00>: Failed to establish a new connection: [Errno 111] Connection refused')': /raw?location=
[2025-07-20T12:57:25.207+0000] {taskinstance.py:2698} ERROR - Task failed with exception
Traceback (most recent call last):
  File "/home/airflow/.local/lib/python3.9/site-packages/urllib3/connection.py", line 174, in _new_conn
    conn = connection.create_connection(
  File "/home/airflow/.local/lib/python3.9/site-packages/urllib3/util/connection.py", line 95, in create_connection
    raise err
  File "/home/airflow/.local/lib/python3.9/site-packages/urllib3/util/connection.py", line 85, in create_connection
    sock.connect(sa)
ConnectionRefusedError: [Errno 111] Connection refused

During handling of the above exception, another exception occurred:

Traceback (most recent call last):
  File "/home/airflow/.local/lib/python3.9/site-packages/urllib3/connectionpool.py", line 715, in urlopen
    httplib_response = self._make_request(
  File "/home/airflow/.local/lib/python3.9/site-packages/urllib3/connectionpool.py", line 416, in _make_request
    conn.request(method, url, **httplib_request_kw)
  File "/home/airflow/.local/lib/python3.9/site-packages/urllib3/connection.py", line 244, in request
    super(HTTPConnection, self).request(method, url, body=body, headers=headers)
  File "/usr/local/lib/python3.9/http/client.py", line 1285, in request
    self._send_request(method, url, body, headers, encode_chunked)
  File "/usr/local/lib/python3.9/http/client.py", line 1331, in _send_request
    self.endheaders(body, encode_chunked=encode_chunked)
  File "/usr/local/lib/python3.9/http/client.py", line 1280, in endheaders
    self._send_output(message_body, encode_chunked=encode_chunked)
  File "/usr/local/lib/python3.9/http/client.py", line 1040, in _send_output
    self.send(msg)
  File "/usr/local/lib/python3.9/http/client.py", line 980, in send
    self.connect()
  File "/home/airflow/.local/lib/python3.9/site-packages/urllib3/connection.py", line 205, in connect
    conn = self._new_conn()
  File "/home/airflow/.local/lib/python3.9/site-packages/urllib3/connection.py", line 186, in _new_conn
    raise NewConnectionError(
urllib3.exceptions.NewConnectionError: <urllib3.connection.HTTPConnection object at 0x785777164f10>: Failed to establish a new connection: [Errno 111] Connection refused

During handling of the above exception, another exception occurred:

Traceback (most recent call last):
  File "/home/airflow/.local/lib/python3.9/site-packages/airflow/models/taskinstance.py", line 433, in _execute_task
    result = execute_callable(context=context, **execute_callable_kwargs)
  File "/home/airflow/.local/lib/python3.9/site-packages/airflow/operators/python.py", line 199, in execute
    return_value = self.execute_callable()
  File "/home/airflow/.local/lib/python3.9/site-packages/airflow/operators/python.py", line 216, in execute_callable
    return self.python_callable(*self.op_args, **self.op_kwargs)
  File "/opt/airflow/code/scraper/ingest_data_raw.py", line 49, in main
    save_dataframe_as_parquet_to_minio(df, f"/{parquet_name}", MINIO_BUCKET)
  File "/opt/airflow/utils/minio_helper.py", line 38, in save_dataframe_as_parquet_to_minio
    if not minio_client.bucket_exists(MINIO_BUCKET):
  File "/home/airflow/.local/lib/python3.9/site-packages/minio/api.py", line 697, in bucket_exists
    self._execute("HEAD", bucket_name)
  File "/home/airflow/.local/lib/python3.9/site-packages/minio/api.py", line 438, in _execute
    region = self._get_region(bucket_name)
  File "/home/airflow/.local/lib/python3.9/site-packages/minio/api.py", line 495, in _get_region
    response = self._url_open(
  File "/home/airflow/.local/lib/python3.9/site-packages/minio/api.py", line 303, in _url_open
    response = self._http.urlopen(
  File "/home/airflow/.local/lib/python3.9/site-packages/urllib3/poolmanager.py", line 376, in urlopen
    response = conn.urlopen(method, u.request_uri, **kw)
  File "/home/airflow/.local/lib/python3.9/site-packages/urllib3/connectionpool.py", line 827, in urlopen
    return self.urlopen(
  File "/home/airflow/.local/lib/python3.9/site-packages/urllib3/connectionpool.py", line 827, in urlopen
    return self.urlopen(
  File "/home/airflow/.local/lib/python3.9/site-packages/urllib3/connectionpool.py", line 827, in urlopen
    return self.urlopen(
  [Previous line repeated 2 more times]
  File "/home/airflow/.local/lib/python3.9/site-packages/urllib3/connectionpool.py", line 799, in urlopen
    retries = retries.increment(
  File "/home/airflow/.local/lib/python3.9/site-packages/urllib3/util/retry.py", line 592, in increment
    raise MaxRetryError(_pool, url, error or ResponseError(cause))
urllib3.exceptions.MaxRetryError: HTTPConnectionPool(host='localhost', port=9000): Max retries exceeded with url: /raw?location= (Caused by NewConnectionError('<urllib3.connection.HTTPConnection object at 0x785777164f10>: Failed to establish a new connection: [Errno 111] Connection refused'))
[2025-07-20T12:57:25.235+0000] {taskinstance.py:1138} INFO - Marking task as UP_FOR_RETRY. dag_id=ETL_Pipeline, task_id=ingest_raw_data, execution_date=20250720T125712, start_date=20250720T125717, end_date=20250720T125725
[2025-07-20T12:57:25.246+0000] {standard_task_runner.py:107} ERROR - Failed to execute job 41 for task ingest_raw_data (HTTPConnectionPool(host='localhost', port=9000): Max retries exceeded with url: /raw?location= (Caused by NewConnectionError('<urllib3.connection.HTTPConnection object at 0x785777164f10>: Failed to establish a new connection: [Errno 111] Connection refused')); 295)
[2025-07-20T12:57:25.269+0000] {local_task_job_runner.py:234} INFO - Task exited with return code 1
[2025-07-20T12:57:25.292+0000] {taskinstance.py:3280} INFO - 0 downstream tasks scheduled from follow-on schedule check
