[2025-07-20T17:36:41.185+0000] {local_task_job_runner.py:120} INFO - ::group::Pre task execution logs
[2025-07-20T17:36:41.195+0000] {taskinstance.py:2076} INFO - Dependencies all met for dep_context=non-requeueable deps ti=<TaskInstance: ETL_Pipeline.load_vectordb manual__2025-07-20T17:36:11.046513+00:00 [queued]>
[2025-07-20T17:36:41.201+0000] {taskinstance.py:2076} INFO - Dependencies all met for dep_context=requeueable deps ti=<TaskInstance: ETL_Pipeline.load_vectordb manual__2025-07-20T17:36:11.046513+00:00 [queued]>
[2025-07-20T17:36:41.202+0000] {taskinstance.py:2306} INFO - Starting attempt 1 of 2
[2025-07-20T17:36:41.210+0000] {taskinstance.py:2330} INFO - Executing <Task(PythonOperator): load_vectordb> on 2025-07-20 17:36:11.046513+00:00
[2025-07-20T17:36:41.219+0000] {standard_task_runner.py:64} INFO - Started process 1005 to run task
[2025-07-20T17:36:41.224+0000] {standard_task_runner.py:90} INFO - Running: ['***', 'tasks', 'run', 'ETL_Pipeline', 'load_vectordb', 'manual__2025-07-20T17:36:11.046513+00:00', '--job-id', '59', '--raw', '--subdir', 'DAGS_FOLDER/etl_dag.py', '--cfg-path', '/tmp/tmpr6hul0mg']
[2025-07-20T17:36:41.227+0000] {standard_task_runner.py:91} INFO - Job 59: Subtask load_vectordb
[2025-07-20T17:36:41.265+0000] {task_command.py:426} INFO - Running <TaskInstance: ETL_Pipeline.load_vectordb manual__2025-07-20T17:36:11.046513+00:00 [running]> on host cc0200432425
[2025-07-20T17:36:41.316+0000] {taskinstance.py:2648} INFO - Exporting env vars: AIRFLOW_CTX_DAG_OWNER='Jhabindra Aryal' AIRFLOW_CTX_DAG_ID='ETL_Pipeline' AIRFLOW_CTX_TASK_ID='load_vectordb' AIRFLOW_CTX_EXECUTION_DATE='2025-07-20T17:36:11.046513+00:00' AIRFLOW_CTX_TRY_NUMBER='1' AIRFLOW_CTX_DAG_RUN_ID='manual__2025-07-20T17:36:11.046513+00:00'
[2025-07-20T17:36:41.317+0000] {taskinstance.py:430} INFO - ::endgroup::
[2025-07-20T17:36:41.326+0000] {logging_mixin.py:188} INFO - Reading embedding data from MinIO...
[2025-07-20T17:36:41.327+0000] {taskinstance.py:441} INFO - ::group::Post task execution logs
[2025-07-20T17:36:41.327+0000] {taskinstance.py:2905} ERROR - Task failed with exception
Traceback (most recent call last):
  File "/home/airflow/.local/lib/python3.10/site-packages/airflow/models/taskinstance.py", line 465, in _execute_task
    result = _execute_callable(context=context, **execute_callable_kwargs)
  File "/home/airflow/.local/lib/python3.10/site-packages/airflow/models/taskinstance.py", line 432, in _execute_callable
    return execute_callable(context=context, **execute_callable_kwargs)
  File "/home/airflow/.local/lib/python3.10/site-packages/airflow/models/baseoperator.py", line 401, in wrapper
    return func(self, *args, **kwargs)
  File "/home/airflow/.local/lib/python3.10/site-packages/airflow/operators/python.py", line 235, in execute
    return_value = self.execute_callable()
  File "/home/airflow/.local/lib/python3.10/site-packages/airflow/operators/python.py", line 252, in execute_callable
    return self.python_callable(*self.op_args, **self.op_kwargs)
  File "/opt/airflow/code/vectordb/vector_db.py", line 54, in main
    print(f"âœ… Successfully loaded {len(ids)} documents into ChromaDB.")
NameError: name 'ids' is not defined. Did you mean: 'id'?
[2025-07-20T17:36:41.340+0000] {taskinstance.py:1206} INFO - Marking task as UP_FOR_RETRY. dag_id=ETL_Pipeline, task_id=load_vectordb, run_id=manual__2025-07-20T17:36:11.046513+00:00, execution_date=20250720T173611, start_date=20250720T173641, end_date=20250720T173641
[2025-07-20T17:36:41.348+0000] {standard_task_runner.py:110} ERROR - Failed to execute job 59 for task load_vectordb (name 'ids' is not defined; 1005)
[2025-07-20T17:36:41.395+0000] {local_task_job_runner.py:243} INFO - Task exited with return code 1
[2025-07-20T17:36:41.408+0000] {taskinstance.py:3503} INFO - 0 downstream tasks scheduled from follow-on schedule check
[2025-07-20T17:36:41.416+0000] {local_task_job_runner.py:222} INFO - ::endgroup::
