[2025-07-20T18:24:29.244+0000] {local_task_job_runner.py:120} INFO - ::group::Pre task execution logs
[2025-07-20T18:24:29.254+0000] {taskinstance.py:2076} INFO - Dependencies all met for dep_context=non-requeueable deps ti=<TaskInstance: ETL_Pipeline.ingest_raw_data manual__2025-07-20T18:23:39.922514+00:00 [queued]>
[2025-07-20T18:24:29.258+0000] {taskinstance.py:2076} INFO - Dependencies all met for dep_context=requeueable deps ti=<TaskInstance: ETL_Pipeline.ingest_raw_data manual__2025-07-20T18:23:39.922514+00:00 [queued]>
[2025-07-20T18:24:29.259+0000] {taskinstance.py:2306} INFO - Starting attempt 3 of 4
[2025-07-20T18:24:29.267+0000] {taskinstance.py:2330} INFO - Executing <Task(PythonOperator): ingest_raw_data> on 2025-07-20 18:23:39.922514+00:00
[2025-07-20T18:24:29.278+0000] {standard_task_runner.py:64} INFO - Started process 1565 to run task
[2025-07-20T18:24:29.282+0000] {standard_task_runner.py:90} INFO - Running: ['***', 'tasks', 'run', 'ETL_Pipeline', 'ingest_raw_data', 'manual__2025-07-20T18:23:39.922514+00:00', '--job-id', '100', '--raw', '--subdir', 'DAGS_FOLDER/etl_dag.py', '--cfg-path', '/tmp/tmpq1qtlnw8']
[2025-07-20T18:24:29.285+0000] {standard_task_runner.py:91} INFO - Job 100: Subtask ingest_raw_data
[2025-07-20T18:24:29.327+0000] {task_command.py:426} INFO - Running <TaskInstance: ETL_Pipeline.ingest_raw_data manual__2025-07-20T18:23:39.922514+00:00 [running]> on host 9c93ad0801dc
[2025-07-20T18:24:29.378+0000] {taskinstance.py:2648} INFO - Exporting env vars: AIRFLOW_CTX_DAG_OWNER='Jhabindra Aryal' AIRFLOW_CTX_DAG_ID='ETL_Pipeline' AIRFLOW_CTX_TASK_ID='ingest_raw_data' AIRFLOW_CTX_EXECUTION_DATE='2025-07-20T18:23:39.922514+00:00' AIRFLOW_CTX_TRY_NUMBER='3' AIRFLOW_CTX_DAG_RUN_ID='manual__2025-07-20T18:23:39.922514+00:00'
[2025-07-20T18:24:29.379+0000] {taskinstance.py:430} INFO - ::endgroup::
[2025-07-20T18:24:30.367+0000] {logging_mixin.py:188} INFO - Saved raw text to data/raw/data
[2025-07-20T18:24:30.371+0000] {logging_mixin.py:188} INFO - Created DataFrame with 574 lines of text
[2025-07-20T18:24:30.374+0000] {connectionpool.py:872} WARNING - Retrying (Retry(total=4, connect=None, read=None, redirect=None, status=None)) after connection broken by 'NewConnectionError('<urllib3.connection.HTTPConnection object at 0x797695f453f0>: Failed to establish a new connection: [Errno 111] Connection refused')': /raw?location=
[2025-07-20T18:24:30.775+0000] {connectionpool.py:872} WARNING - Retrying (Retry(total=3, connect=None, read=None, redirect=None, status=None)) after connection broken by 'NewConnectionError('<urllib3.connection.HTTPConnection object at 0x797695f47e80>: Failed to establish a new connection: [Errno 111] Connection refused')': /raw?location=
[2025-07-20T18:24:31.583+0000] {connectionpool.py:872} WARNING - Retrying (Retry(total=2, connect=None, read=None, redirect=None, status=None)) after connection broken by 'NewConnectionError('<urllib3.connection.HTTPConnection object at 0x797695f47cd0>: Failed to establish a new connection: [Errno 111] Connection refused')': /raw?location=
[2025-07-20T18:24:33.188+0000] {connectionpool.py:872} WARNING - Retrying (Retry(total=1, connect=None, read=None, redirect=None, status=None)) after connection broken by 'NewConnectionError('<urllib3.connection.HTTPConnection object at 0x797695f47b20>: Failed to establish a new connection: [Errno 111] Connection refused')': /raw?location=
[2025-07-20T18:24:36.389+0000] {connectionpool.py:872} WARNING - Retrying (Retry(total=0, connect=None, read=None, redirect=None, status=None)) after connection broken by 'NewConnectionError('<urllib3.connection.HTTPConnection object at 0x797695f47970>: Failed to establish a new connection: [Errno 111] Connection refused')': /raw?location=
[2025-07-20T18:24:36.390+0000] {taskinstance.py:441} INFO - ::group::Post task execution logs
[2025-07-20T18:24:36.391+0000] {taskinstance.py:2905} ERROR - Task failed with exception
Traceback (most recent call last):
  File "/home/airflow/.local/lib/python3.10/site-packages/urllib3/connection.py", line 203, in _new_conn
    sock = connection.create_connection(
  File "/home/airflow/.local/lib/python3.10/site-packages/urllib3/util/connection.py", line 85, in create_connection
    raise err
  File "/home/airflow/.local/lib/python3.10/site-packages/urllib3/util/connection.py", line 73, in create_connection
    sock.connect(sa)
ConnectionRefusedError: [Errno 111] Connection refused

The above exception was the direct cause of the following exception:

Traceback (most recent call last):
  File "/home/airflow/.local/lib/python3.10/site-packages/urllib3/connectionpool.py", line 791, in urlopen
    response = self._make_request(
  File "/home/airflow/.local/lib/python3.10/site-packages/urllib3/connectionpool.py", line 497, in _make_request
    conn.request(
  File "/home/airflow/.local/lib/python3.10/site-packages/urllib3/connection.py", line 395, in request
    self.endheaders()
  File "/usr/local/lib/python3.10/http/client.py", line 1278, in endheaders
    self._send_output(message_body, encode_chunked=encode_chunked)
  File "/usr/local/lib/python3.10/http/client.py", line 1038, in _send_output
    self.send(msg)
  File "/usr/local/lib/python3.10/http/client.py", line 976, in send
    self.connect()
  File "/home/airflow/.local/lib/python3.10/site-packages/urllib3/connection.py", line 243, in connect
    self.sock = self._new_conn()
  File "/home/airflow/.local/lib/python3.10/site-packages/urllib3/connection.py", line 218, in _new_conn
    raise NewConnectionError(
urllib3.exceptions.NewConnectionError: <urllib3.connection.HTTPConnection object at 0x797695f45cc0>: Failed to establish a new connection: [Errno 111] Connection refused

The above exception was the direct cause of the following exception:

Traceback (most recent call last):
  File "/home/airflow/.local/lib/python3.10/site-packages/airflow/models/taskinstance.py", line 465, in _execute_task
    result = _execute_callable(context=context, **execute_callable_kwargs)
  File "/home/airflow/.local/lib/python3.10/site-packages/airflow/models/taskinstance.py", line 432, in _execute_callable
    return execute_callable(context=context, **execute_callable_kwargs)
  File "/home/airflow/.local/lib/python3.10/site-packages/airflow/models/baseoperator.py", line 401, in wrapper
    return func(self, *args, **kwargs)
  File "/home/airflow/.local/lib/python3.10/site-packages/airflow/operators/python.py", line 235, in execute
    return_value = self.execute_callable()
  File "/home/airflow/.local/lib/python3.10/site-packages/airflow/operators/python.py", line 252, in execute_callable
    return self.python_callable(*self.op_args, **self.op_kwargs)
  File "/opt/airflow/code/scraper/ingest_data_raw.py", line 49, in main
    save_dataframe_as_parquet_to_minio(df, f"/{parquet_name}", MINIO_BUCKET)
  File "/opt/airflow/utils/minio_helper.py", line 41, in save_dataframe_as_parquet_to_minio
    if not minio_client.bucket_exists(MINIO_BUCKET):
  File "/home/airflow/.local/lib/python3.10/site-packages/minio/api.py", line 697, in bucket_exists
    self._execute("HEAD", bucket_name)
  File "/home/airflow/.local/lib/python3.10/site-packages/minio/api.py", line 438, in _execute
    region = self._get_region(bucket_name)
  File "/home/airflow/.local/lib/python3.10/site-packages/minio/api.py", line 495, in _get_region
    response = self._url_open(
  File "/home/airflow/.local/lib/python3.10/site-packages/minio/api.py", line 303, in _url_open
    response = self._http.urlopen(
  File "/home/airflow/.local/lib/python3.10/site-packages/urllib3/poolmanager.py", line 443, in urlopen
    response = conn.urlopen(method, u.request_uri, **kw)
  File "/home/airflow/.local/lib/python3.10/site-packages/urllib3/connectionpool.py", line 875, in urlopen
    return self.urlopen(
  File "/home/airflow/.local/lib/python3.10/site-packages/urllib3/connectionpool.py", line 875, in urlopen
    return self.urlopen(
  File "/home/airflow/.local/lib/python3.10/site-packages/urllib3/connectionpool.py", line 875, in urlopen
    return self.urlopen(
  [Previous line repeated 2 more times]
  File "/home/airflow/.local/lib/python3.10/site-packages/urllib3/connectionpool.py", line 845, in urlopen
    retries = retries.increment(
  File "/home/airflow/.local/lib/python3.10/site-packages/urllib3/util/retry.py", line 515, in increment
    raise MaxRetryError(_pool, url, reason) from reason  # type: ignore[arg-type]
urllib3.exceptions.MaxRetryError: HTTPConnectionPool(host='localhost', port=9000): Max retries exceeded with url: /raw?location= (Caused by NewConnectionError('<urllib3.connection.HTTPConnection object at 0x797695f45cc0>: Failed to establish a new connection: [Errno 111] Connection refused'))
[2025-07-20T18:24:36.419+0000] {taskinstance.py:1206} INFO - Marking task as UP_FOR_RETRY. dag_id=ETL_Pipeline, task_id=ingest_raw_data, run_id=manual__2025-07-20T18:23:39.922514+00:00, execution_date=20250720T182339, start_date=20250720T182429, end_date=20250720T182436
[2025-07-20T18:24:36.436+0000] {standard_task_runner.py:110} ERROR - Failed to execute job 100 for task ingest_raw_data (HTTPConnectionPool(host='localhost', port=9000): Max retries exceeded with url: /raw?location= (Caused by NewConnectionError('<urllib3.connection.HTTPConnection object at 0x797695f45cc0>: Failed to establish a new connection: [Errno 111] Connection refused')); 1565)
[2025-07-20T18:24:36.476+0000] {local_task_job_runner.py:243} INFO - Task exited with return code 1
[2025-07-20T18:24:36.490+0000] {taskinstance.py:3503} INFO - 0 downstream tasks scheduled from follow-on schedule check
[2025-07-20T18:24:36.493+0000] {local_task_job_runner.py:222} INFO - ::endgroup::
