[2025-07-20T18:25:54.755+0000] {local_task_job_runner.py:120} INFO - ::group::Pre task execution logs
[2025-07-20T18:25:54.767+0000] {taskinstance.py:2076} INFO - Dependencies all met for dep_context=non-requeueable deps ti=<TaskInstance: ETL_Pipeline.bronze_transform manual__2025-07-20T18:23:39.922514+00:00 [queued]>
[2025-07-20T18:25:54.773+0000] {taskinstance.py:2076} INFO - Dependencies all met for dep_context=requeueable deps ti=<TaskInstance: ETL_Pipeline.bronze_transform manual__2025-07-20T18:23:39.922514+00:00 [queued]>
[2025-07-20T18:25:54.774+0000] {taskinstance.py:2306} INFO - Starting attempt 1 of 2
[2025-07-20T18:25:54.783+0000] {taskinstance.py:2330} INFO - Executing <Task(PythonOperator): bronze_transform> on 2025-07-20 18:23:39.922514+00:00
[2025-07-20T18:25:54.794+0000] {standard_task_runner.py:64} INFO - Started process 1682 to run task
[2025-07-20T18:25:54.799+0000] {standard_task_runner.py:90} INFO - Running: ['***', 'tasks', 'run', 'ETL_Pipeline', 'bronze_transform', 'manual__2025-07-20T18:23:39.922514+00:00', '--job-id', '103', '--raw', '--subdir', 'DAGS_FOLDER/etl_dag.py', '--cfg-path', '/tmp/tmphzj7fmt5']
[2025-07-20T18:25:54.803+0000] {standard_task_runner.py:91} INFO - Job 103: Subtask bronze_transform
[2025-07-20T18:25:54.852+0000] {task_command.py:426} INFO - Running <TaskInstance: ETL_Pipeline.bronze_transform manual__2025-07-20T18:23:39.922514+00:00 [running]> on host 9c93ad0801dc
[2025-07-20T18:25:54.915+0000] {taskinstance.py:2648} INFO - Exporting env vars: AIRFLOW_CTX_DAG_OWNER='Jhabindra Aryal' AIRFLOW_CTX_DAG_ID='ETL_Pipeline' AIRFLOW_CTX_TASK_ID='bronze_transform' AIRFLOW_CTX_EXECUTION_DATE='2025-07-20T18:23:39.922514+00:00' AIRFLOW_CTX_TRY_NUMBER='1' AIRFLOW_CTX_DAG_RUN_ID='manual__2025-07-20T18:23:39.922514+00:00'
[2025-07-20T18:25:54.916+0000] {taskinstance.py:430} INFO - ::endgroup::
[2025-07-20T18:25:54.929+0000] {connectionpool.py:872} WARNING - Retrying (Retry(total=4, connect=None, read=None, redirect=None, status=None)) after connection broken by 'NewConnectionError('<urllib3.connection.HTTPConnection object at 0x797695f486a0>: Failed to establish a new connection: [Errno 111] Connection refused')': /raw?location=
[2025-07-20T18:25:55.331+0000] {connectionpool.py:872} WARNING - Retrying (Retry(total=3, connect=None, read=None, redirect=None, status=None)) after connection broken by 'NewConnectionError('<urllib3.connection.HTTPConnection object at 0x797695f48430>: Failed to establish a new connection: [Errno 111] Connection refused')': /raw?location=
[2025-07-20T18:25:56.133+0000] {connectionpool.py:872} WARNING - Retrying (Retry(total=2, connect=None, read=None, redirect=None, status=None)) after connection broken by 'NewConnectionError('<urllib3.connection.HTTPConnection object at 0x797695f496f0>: Failed to establish a new connection: [Errno 111] Connection refused')': /raw?location=
[2025-07-20T18:25:57.736+0000] {connectionpool.py:872} WARNING - Retrying (Retry(total=1, connect=None, read=None, redirect=None, status=None)) after connection broken by 'NewConnectionError('<urllib3.connection.HTTPConnection object at 0x797695f48d00>: Failed to establish a new connection: [Errno 111] Connection refused')': /raw?location=
[2025-07-20T18:26:00.940+0000] {connectionpool.py:872} WARNING - Retrying (Retry(total=0, connect=None, read=None, redirect=None, status=None)) after connection broken by 'NewConnectionError('<urllib3.connection.HTTPConnection object at 0x797695f49a80>: Failed to establish a new connection: [Errno 111] Connection refused')': /raw?location=
[2025-07-20T18:26:00.941+0000] {taskinstance.py:441} INFO - ::group::Post task execution logs
[2025-07-20T18:26:00.942+0000] {taskinstance.py:2905} ERROR - Task failed with exception
Traceback (most recent call last):
  File "/home/airflow/.local/lib/python3.10/site-packages/urllib3/connection.py", line 203, in _new_conn
    sock = connection.create_connection(
  File "/home/airflow/.local/lib/python3.10/site-packages/urllib3/util/connection.py", line 85, in create_connection
    raise err
  File "/home/airflow/.local/lib/python3.10/site-packages/urllib3/util/connection.py", line 73, in create_connection
    sock.connect(sa)
ConnectionRefusedError: [Errno 111] Connection refused

The above exception was the direct cause of the following exception:

Traceback (most recent call last):
  File "/home/airflow/.local/lib/python3.10/site-packages/urllib3/connectionpool.py", line 791, in urlopen
    response = self._make_request(
  File "/home/airflow/.local/lib/python3.10/site-packages/urllib3/connectionpool.py", line 497, in _make_request
    conn.request(
  File "/home/airflow/.local/lib/python3.10/site-packages/urllib3/connection.py", line 395, in request
    self.endheaders()
  File "/usr/local/lib/python3.10/http/client.py", line 1278, in endheaders
    self._send_output(message_body, encode_chunked=encode_chunked)
  File "/usr/local/lib/python3.10/http/client.py", line 1038, in _send_output
    self.send(msg)
  File "/usr/local/lib/python3.10/http/client.py", line 976, in send
    self.connect()
  File "/home/airflow/.local/lib/python3.10/site-packages/urllib3/connection.py", line 243, in connect
    self.sock = self._new_conn()
  File "/home/airflow/.local/lib/python3.10/site-packages/urllib3/connection.py", line 218, in _new_conn
    raise NewConnectionError(
urllib3.exceptions.NewConnectionError: <urllib3.connection.HTTPConnection object at 0x797695f49180>: Failed to establish a new connection: [Errno 111] Connection refused

The above exception was the direct cause of the following exception:

Traceback (most recent call last):
  File "/home/airflow/.local/lib/python3.10/site-packages/airflow/models/taskinstance.py", line 465, in _execute_task
    result = _execute_callable(context=context, **execute_callable_kwargs)
  File "/home/airflow/.local/lib/python3.10/site-packages/airflow/models/taskinstance.py", line 432, in _execute_callable
    return execute_callable(context=context, **execute_callable_kwargs)
  File "/home/airflow/.local/lib/python3.10/site-packages/airflow/models/baseoperator.py", line 401, in wrapper
    return func(self, *args, **kwargs)
  File "/home/airflow/.local/lib/python3.10/site-packages/airflow/operators/python.py", line 235, in execute
    return_value = self.execute_callable()
  File "/home/airflow/.local/lib/python3.10/site-packages/airflow/operators/python.py", line 252, in execute_callable
    return self.python_callable(*self.op_args, **self.op_kwargs)
  File "/opt/airflow/code/etl/bronze.py", line 25, in main
    df = read_parquet_from_minio(RAW_BUCKET, file_name)
  File "/opt/airflow/utils/minio_helper.py", line 71, in read_parquet_from_minio
    response = minio_client.get_object(bucket, object_name)
  File "/home/airflow/.local/lib/python3.10/site-packages/minio/api.py", line 1254, in get_object
    return self._execute(
  File "/home/airflow/.local/lib/python3.10/site-packages/minio/api.py", line 438, in _execute
    region = self._get_region(bucket_name)
  File "/home/airflow/.local/lib/python3.10/site-packages/minio/api.py", line 495, in _get_region
    response = self._url_open(
  File "/home/airflow/.local/lib/python3.10/site-packages/minio/api.py", line 303, in _url_open
    response = self._http.urlopen(
  File "/home/airflow/.local/lib/python3.10/site-packages/urllib3/poolmanager.py", line 443, in urlopen
    response = conn.urlopen(method, u.request_uri, **kw)
  File "/home/airflow/.local/lib/python3.10/site-packages/urllib3/connectionpool.py", line 875, in urlopen
    return self.urlopen(
  File "/home/airflow/.local/lib/python3.10/site-packages/urllib3/connectionpool.py", line 875, in urlopen
    return self.urlopen(
  File "/home/airflow/.local/lib/python3.10/site-packages/urllib3/connectionpool.py", line 875, in urlopen
    return self.urlopen(
  [Previous line repeated 2 more times]
  File "/home/airflow/.local/lib/python3.10/site-packages/urllib3/connectionpool.py", line 845, in urlopen
    retries = retries.increment(
  File "/home/airflow/.local/lib/python3.10/site-packages/urllib3/util/retry.py", line 515, in increment
    raise MaxRetryError(_pool, url, reason) from reason  # type: ignore[arg-type]
urllib3.exceptions.MaxRetryError: HTTPConnectionPool(host='localhost', port=9000): Max retries exceeded with url: /raw?location= (Caused by NewConnectionError('<urllib3.connection.HTTPConnection object at 0x797695f49180>: Failed to establish a new connection: [Errno 111] Connection refused'))
[2025-07-20T18:26:00.966+0000] {taskinstance.py:1206} INFO - Marking task as UP_FOR_RETRY. dag_id=ETL_Pipeline, task_id=bronze_transform, run_id=manual__2025-07-20T18:23:39.922514+00:00, execution_date=20250720T182339, start_date=20250720T182554, end_date=20250720T182600
[2025-07-20T18:26:00.974+0000] {standard_task_runner.py:110} ERROR - Failed to execute job 103 for task bronze_transform (HTTPConnectionPool(host='localhost', port=9000): Max retries exceeded with url: /raw?location= (Caused by NewConnectionError('<urllib3.connection.HTTPConnection object at 0x797695f49180>: Failed to establish a new connection: [Errno 111] Connection refused')); 1682)
[2025-07-20T18:26:01.004+0000] {local_task_job_runner.py:243} INFO - Task exited with return code 1
[2025-07-20T18:26:01.016+0000] {taskinstance.py:3503} INFO - 0 downstream tasks scheduled from follow-on schedule check
[2025-07-20T18:26:01.018+0000] {local_task_job_runner.py:222} INFO - ::endgroup::
